Workbook

Sheet Концепции и оценки
A1: Фаза 1: Выбор концепции проекта
A3: 1. Альтернативы
A4: Код | B4: Концепции
A5: A1 | B5: Система управления заявками на обслуживание
A6: A2 | B6: Фитнес-приложение с геймификацией
A7: A3 | B7: Сервис совместного выбора и просмотра фильмов
A8: A4 | B8: Сервис персонализированных погодных рекомендаций
A11: 2. Критерии и оценка(п - пессимистичная, о - ожидаемая, опт - оптимистичность)
A12: Код | B12: Критерии | H12: Тип | I12: Бохолдин Д.Ю. | L12: Шульга Н.О. | O12: Ушаков Д.С.
I13: п | J13: о | K13: опт | L13: п | M13: о | N13: опт | O13: п | P13: о | Q13: опт
A14: К1 | B14: Масштабируемость | H14: выгода | I14: 4 | J14: 6 | K14: 9 | L14: 5 | M14: 6 | N14: 8 | O14: 6 | P14: 7 | Q14: 8
A15: К2 | B15: Трудоемкость разработки MVP | H15: затраты | I15: 4 | J15: 7 | K15: 10 | L15: 7 | M15: 9 | N15: 10 | O15: 7 | P15: 8 | Q15: 8
A16: К3 | B16: Практическая полезность проекта | H16: выгода | I16: 5 | J16: 7 | K16: 9 | L16: 7 | M16: 8 | N16: 10 | O16: 7 | P16: 8 | Q16: 10
A17: К4 | B17: Функциональная уникальность | H17: выгода | I17: 3 | J17: 7 | K17: 7 | L17: 4 | M17: 6 | N17: 7 | O17: 5 | P17: 6 | Q17: 7
A19: 3. Оценка Альтернатив по критериям (1...10)
A20: Критерии | B20: Альтернативы | D20: Бохолдин Д.Ю. | G20: Шульга Н.О. | J20: Ушаков Д.С.
D21: п | E21: о | F21: опт | G21: п | H21: о | I21: опт | J21: п | K21: о | L21: опт
A22: К1 | B22: A1 | D22: 6 | E22: 7 | F22: 10 | G22: 7 | H22: 8 | I22: 9 | J22: 7 | K22: 8 | L22: 9
A23: K1 | B23: A2 | D23: 2 | E23: 4 | F23: 6 | G23: 6 | H23: 8 | I23: 9 | J23: 6 | K23: 7 | L23: 8
A24: K1 | B24: A3 | D24: 2 | E24: 5 | F24: 6 | G24: 3 | H24: 5 | I24: 7 | J24: 4 | K24: 5 | L24: 7
A25: K1 | B25: A4 | D25: 5 | E25: 7 | F25: 9 | G25: 5 | H25: 7 | I25: 8 | J25: 5 | K25: 6 | L25: 7
A26: К2 | B26: A1 | D26: 6 | E26: 7 | F26: 9 | G26: 3 | H26: 5 | I26: 7 | J26: 7 | K26: 8 | L26: 9
A27: К2 | B27: A2 | D27: 2 | E27: 4 | F27: 6 | G27: 5 | H27: 7 | I27: 9 | J27: 5 | K27: 6 | L27: 7
A28: К2 | B28: A3 | D28: 4 | E28: 6 | F28: 8 | G28: 7 | H28: 9 | I28: 10 | J28: 7 | K28: 8 | L28: 9
A29: К2 | B29: A4 | D29: 4 | E29: 6 | F29: 7 | G29: 5 | H29: 7 | I29: 9 | J29: 5 | K29: 6 | L29: 7
A30: К3 | B30: A1 | D30: 4 | E30: 5 | F30: 7 | G30: 8 | H30: 9 | I30: 10 | J30: 8 | K30: 9 | L30: 10
A31: К3 | B31: A2 | D31: 5 | E31: 7 | F31: 9 | G31: 8 | H31: 9 | I31: 10 | J31: 6 | K31: 8 | L31: 9
A32: К3 | B32: A3 | D32: 4 | E32: 5 | F32: 7 | G32: 5 | H32: 6 | I32: 8 | J32: 5 | K32: 6 | L32: 7
A33: К3 | B33: A4 | D33: 7 | E33: 8 | F33: 9 | G33: 7 | H33: 8 | I33: 9 | J33: 6 | K33: 7 | L33: 8
... A37: К4 | B37: A4 | D37: 6 | E37: 7 | F37: 8 | G37: 7 | H37: 8 | I37: 10 | J37: 7 | K37: 8 | L37: 9

Sheet Topsis
A1: Нечёткий коллективный Topsis
A3: 1. Агрегированные веса критериев (l=min, m =сред. знач, u = max)
A4: Критерий | B4: l | C4: m | D4: u
A5: К1 | B5: =MIN('Концепции и оценки'!I14,'Концепции и оценки'!L14,'Концепции и оценки'!O14) -> 4 | C5: =AVERAGE('Концепции и оценки'!J14,'Концепции и оценки'!M14,'Концепции и оценки'!P14) -> 6.3333333 | D5: =MAX('Концепции и оценки'!K14,'Концепции и оценки'!N14,'Концепции и оценки'!Q14) -> 9
A6: К2 | B6: =MIN('Концепции и оценки'!I15,'Концепции и оценки'!L15,'Концепции и оценки'!O15) -> 4 | C6: =AVERAGE('Концепции и оценки'!J15,'Концепции и оценки'!M15,'Концепции и оценки'!P15) -> 8 | D6: =MAX('Концепции и оценки'!K15,'Концепции и оценки'!N15,'Концепции и оценки'!Q15) -> 10
A7: К3 | B7: =MIN('Концепции и оценки'!I16,'Концепции и оценки'!L16,'Концепции и оценки'!O16) -> 5 | C7: =AVERAGE('Концепции и оценки'!J16,'Концепции и оценки'!M16,'Концепции и оценки'!P16) -> 7.6666667 | D7: =MAX('Концепции и оценки'!K16,'Концепции и оценки'!N16,'Концепции и оценки'!Q16) -> 10
A8: К4 | B8: =MIN('Концепции и оценки'!I17,'Концепции и оценки'!L17,'Концепции и оценки'!O17) -> 3 | C8: =AVERAGE('Концепции и оценки'!J17,'Концепции и оценки'!M17,'Концепции и оценки'!P17) -> 6.3333333 | D8: =MAX('Концепции и оценки'!K17,'Концепции и оценки'!N17,'Концепции и оценки'!Q17) -> 7
A10: Нормализированные веса критериев
A11: Критерий | B11: w(l) | C11: w(m) | D11: w(u) | E11: Тип
A12: К1 | B12: =B5/MAX($D$5:$D$8) -> 0.4 | C12: =C5/MAX($D$5:$D$8) -> 0.63333333 | D12: =D5/MAX($D$5:$D$8) -> 0.9 | E12: Выгода
A13: К2 | B13: =B6/MAX($D$5:$D$8) -> 0.4 | C13: =C6/MAX($D$5:$D$8) -> 0.8 | D13: =D6/MAX($D$5:$D$8) -> 1 | E13: Затраты
A14: К3 | B14: =B7/MAX($D$5:$D$8) -> 0.5 | C14: =C7/MAX($D$5:$D$8) -> 0.76666667 | D14: =D7/MAX($D$5:$D$8) -> 1 | E14: Выгода
A15: К4 | B15: =B8/MAX($D$5:$D$8) -> 0.3 | C15: =C8/MAX($D$5:$D$8) -> 0.63333333 | D15: =D8/MAX($D$5:$D$8) -> 0.7 | E15: Выгода
A17: 2. Агрегированная нечёткая матрица решений
A18: Альтернатив | B18: K1 | E18: K2 | H18: K3 | K18: K4
B19: l | C19: m | D19: u | E19: l | F19: m | G19: u | H19: l | I19: m | J19: u | K19: l | L19: m | M19: u
A20: А1 | B20: =MIN('Концепции и оценки'!D22,'Концепции и оценки'!G22,'Концепции и оценки'!J22) -> 6 | C20: =AVERAGE('Концепции и оценки'!E22,'Концепции и оценки'!H22,'Концепции и оценки'!K22) -> 7.6666667 | D20: =MAX('Концепции и оценки'!F22,'Концепции и оценки'!I22,'Концепции и оценки'!L22) -> 10 | E20: =MIN('Концепции и оценки'!D26,'Концепции и оценки'!G26,'Концепции и оценки'!J26) -> 3 | F20: =AVERAGE('Концепции и оценки'!E26,'Концепции и оценки'!H26,'Концепции и оценки'!K26) -> 6.6666667 | G20: =MAX('Концепции и оценки'!F26,'Концепции и оценки'!I26,'Концепции и оценки'!L26) -> 9 | H20: =MIN('Концепции и оценки'!D30,'Концепции и оценки'!G30,'Концепции и оценки'!J30) -> 4 | I20: =AVERAGE('Концепции и оценки'!E30,'Концепции и оценки'!H30,'Концепции и оценки'!K30) -> 7.6666667 | J20: =MAX('Концепции и оценки'!F30,'Концепции и оценки'!I30,'Концепции и оценки'!L30) -> 10 | K20: =MIN('Концепции и оценки'!D34,'Концепции и оценки'!G34,'Концепции и оценки'!J34) -> 3 | L20: =AVERAGE('Концепции и оценки'!E34,'Концепции и оценки'!H34,'Концепции и оценки'!K34) -> 5 | M20: =MAX('Концепции и оценки'!F34,'Концепции и оценки'!I34,'Концепции и оценки'!L34) -> 7
A21: А2 | B21: =MIN('Концепции и оценки'!D23,'Концепции и оценки'!G23,'Концепции и оценки'!J23) -> 2 | C21: =AVERAGE('Концепции и оценки'!E23,'Концепции и оценки'!H23,'Концепции и оценки'!K23) -> 6.3333333 | D21: =MAX('Концепции и оценки'!F23,'Концепции и оценки'!I23,'Концепции и оценки'!L23) -> 9 | E21: =MIN('Концепции и оценки'!D27,'Концепции и оценки'!G27,'Концепции и оценки'!J27) -> 2 | F21: =AVERAGE('Концепции и оценки'!E27,'Концепции и оценки'!H27,'Концепции и оценки'!K27) -> 5.6666667 | G21: =MAX('Концепции и оценки'!F27,'Концепции и оценки'!I27,'Концепции и оценки'!L27) -> 9 | H21: =MIN('Концепции и оценки'!D31,'Концепции и оценки'!G31,'Концепции и оценки'!J31) -> 5 | I21: =AVERAGE('Концепции и оценки'!E31,'Концепции и оценки'!H31,'Концепции и оценки'!K31) -> 8 | J21: =MAX('Концепции и оценки'!F31,'Концепции и оценки'!I31,'Концепции и оценки'!L31) -> 10 | K21: =MIN('Концепции и оценки'!D35,'Концепции и оценки'!G35,'Концепции и оценки'!J35) -> 3 | L21: =AVERAGE('Концепции и оценки'!E35,'Концепции и оценки'!H35,'Концепции и оценки'!K35) -> 7 | M21: =MAX('Концепции и оценки'!F35,'Концепции и оценки'!I35,'Концепции и оценки'!L35) -> 9
A22: А3 | B22: =MIN('Концепции и оценки'!D24,'Концепции и оценки'!G24,'Концепции и оценки'!J24) -> 2 | C22: =AVERAGE('Концепции и оценки'!E24,'Концепции и оценки'!H24,'Концепции и оценки'!K24) -> 5 | D22: =MAX('Концепции и оценки'!F24,'Концепции и оценки'!I24,'Концепции и оценки'!L24) -> 7 | E22: =MIN('Концепции и оценки'!D28,'Концепции и оценки'!G28,'Концепции и оценки'!J28) -> 4 | F22: =AVERAGE('Концепции и оценки'!E28,'Концепции и оценки'!H28,'Концепции и оценки'!K28) -> 7.6666667 | G22: =MAX('Концепции и оценки'!F28,'Концепции и оценки'!I28,'Концепции и оценки'!L28) -> 10 | H22: =MIN('Концепции и оценки'!D32,'Концепции и оценки'!G32,'Концепции и оценки'!J32) -> 4 | I22: =AVERAGE('Концепции и оценки'!E32,'Концепции и оценки'!H32,'Концепции и оценки'!K32) -> 5.6666667 | J22: =MAX('Концепции и оценки'!F32,'Концепции и оценки'!I32,'Концепции и оценки'!L32) -> 8 | K22: =MIN('Концепции и оценки'!D36,'Концепции и оценки'!G36,'Концепции и оценки'!J36) -> 5 | L22: =AVERAGE('Концепции и оценки'!E36,'Концепции и оценки'!H36,'Концепции и оценки'!K36) -> 7 | M22: =MAX('Концепции и оценки'!F36,'Концепции и оценки'!I36,'Концепции и оценки'!L36) -> 9
A23: А4 | B23: =MIN('Концепции и оценки'!D25,'Концепции и оценки'!G25,'Концепции и оценки'!J25) -> 5 | C23: =AVERAGE('Концепции и оценки'!E25,'Концепции и оценки'!H25,'Концепции и оценки'!K25) -> 6.6666667 | D23: =MAX('Концепции и оценки'!F25,'Концепции и оценки'!I25,'Концепции и оценки'!L25) -> 9 | E23: =MIN('Концепции и оценки'!D29,'Концепции и оценки'!G29,'Концепции и оценки'!J29) -> 4 | F23: =AVERAGE('Концепции и оценки'!E29,'Концепции и оценки'!H29,'Концепции и оценки'!K29) -> 6.3333333 | G23: =MAX('Концепции и оценки'!F29,'Концепции и оценки'!I29,'Концепции и оценки'!L29) -> 9 | H23: =MIN('Концепции и оценки'!D33,'Концепции и оценки'!G33,'Концепции и оценки'!J33) -> 6 | I23: =AVERAGE('Концепции и оценки'!E33,'Концепции и оценки'!H33,'Концепции и оценки'!K33) -> 7.6666667 | J23: =MAX('Концепции и оценки'!F33,'Концепции и оценки'!I33,'Концепции и оценки'!L33) -> 9 | K23: =MIN('Концепции и оценки'!D37,'Концепции и оценки'!G37,'Концепции и оценки'!J37) -> 6 | L23: =AVERAGE('Концепции и оценки'!E37,'Концепции и оценки'!H37,'Концепции и оценки'!K37) -> 7.6666667 | M23: =MAX('Концепции и оценки'!F37,'Концепции и оценки'!I37,'Концепции и оценки'!L37) -> 10
A25: 3. Нормализированная матрицы решений
A26: Альтернатив | B26: K1 | E26: K2 | H26: K3 | K26: K4
B27: l | C27: m | D27: u | E27: l | F27: m | G27: u | H27: l | I27: m | J27: u | K27: l | L27: m | M27: u
A28: А1 | B28: =B20/MAX($D$20:$D$23) -> 0.6 | C28: =C20/MAX($D$20:$D$23) -> 0.76666667 | D28: =D20/MAX($D$20:$D$23) -> 1 | E28: =MIN($E$20:$E$23)/G20 -> 0.22222222 | F28: =MIN($E$20:$E$23)/F20 -> 0.3 | G28: =MIN($E$20:$E$23)/E20 -> 0.66666667 | H28: =H20/MAX($J$20:$J$23) -> 0.4 | I28: =I20/MAX($J$20:$J$23) -> 0.76666667 | J28: =J20/MAX($J$20:$J$23) -> 1 | K28: =K20/MAX($M$20:$M$23) -> 0.3 | L28: =L20/MAX($M$20:$M$23) -> 0.5 | M28: =M20/MAX($M$20:$M$23) -> 0.7
A29: А2 | B29: =B21/MAX($D$20:$D$23) -> 0.2 | C29: =C21/MAX($D$20:$D$23) -> 0.63333333 | D29: =D21/MAX($D$20:$D$23) -> 0.9 | E29: =MIN($E$20:$E$23)/G21 -> 0.22222222 | F29: =MIN($E$20:$E$23)/F21 -> 0.35294118 | G29: =MIN($E$20:$E$23)/E21 -> 1 | H29: =H21/MAX($J$20:$J$23) -> 0.5 | I29: =I21/MAX($J$20:$J$23) -> 0.8 | J29: =J21/MAX($J$20:$J$23) -> 1 | K29: =K21/MAX($M$20:$M$23) -> 0.3 | L29: =L21/MAX($M$20:$M$23) -> 0.7 | M29: =M21/MAX($M$20:$M$23) -> 0.9
A30: А3 | B30: =B22/MAX($D$20:$D$23) -> 0.2 | C30: =C22/MAX($D$20:$D$23) -> 0.5 | D30: =D22/MAX($D$20:$D$23) -> 0.7 | E30: =MIN($E$20:$E$23)/G22 -> 0.2 | F30: =MIN($E$20:$E$23)/F22 -> 0.26086957 | G30: =MIN($E$20:$E$23)/E22 -> 0.5 | H30: =H22/MAX($J$20:$J$23) -> 0.4 | I30: =I22/MAX($J$20:$J$23) -> 0.56666667 | J30: =J22/MAX($J$20:$J$23) -> 0.8 | K30: =K22/MAX($M$20:$M$23) -> 0.5 | L30: =L22/MAX($M$20:$M$23) -> 0.7 | M30: =M22/MAX($M$20:$M$23) -> 0.9
A31: А4 | B31: =B23/MAX($D$20:$D$23) -> 0.5 | C31: =C23/MAX($D$20:$D$23) -> 0.66666667 | D31: =D23/MAX($D$20:$D$23) -> 0.9 | E31: =MIN($E$20:$E$23)/G23 -> 0.22222222 | F31: =MIN($E$20:$E$23)/F23 -> 0.31578947 | G31: =MIN($E$20:$E$23)/E23 -> 0.5 | H31: =H23/MAX($J$20:$J$23) -> 0.6 | I31: =I23/MAX($J$20:$J$23) -> 0.76666667 | J31: =J23/MAX($J$20:$J$23) -> 0.9 | K31: =K23/MAX($M$20:$M$23) -> 0.6 | L31: =L23/MAX($M$20:$M$23) -> 0.76666667 | M31: =M23/MAX($M$20:$M$23) -> 1
A33: 4. Взвешанная нормализированная матрица решений
A34: Альтернатив | B34: K1 | E34: K2 | H34: K3 | K34: K4
B35: l | C35: m | D35: u | E35: l | F35: m | G35: u | H35: l | I35: m | J35: u | K35: l | L35: m | M35: u
A36: А1 | B36: =B$12*B28 -> 0.24 | C36: =C$12*C28 -> 0.48555556 | D36: =D$12*D28 -> 0.9 | E36: =B$13*E28 -> 0.088888889 | F36: =C$13*F28 -> 0.24 | G36: =D$13*G28 -> 0.66666667 | H36: =B$14*H28 -> 0.2 | I36: =C$14*I28 -> 0.58777778 | J36: =D$14*J28 -> 1 | K36: =B$15*K28 -> 0.09 | L36: =C$15*L28 -> 0.31666667 | M36: =D$15*M28 -> 0.49
A37: А2 | B37: =B$12*B29 -> 0.08 | C37: =C$12*C29 -> 0.40111111 | D37: =D$12*D29 -> 0.81 | E37: =B$13*E29 -> 0.088888889 | F37: =C$13*F29 -> 0.28235294 | G37: =D$13*G29 -> 1 | H37: =B$14*H29 -> 0.25 | I37: =C$14*I29 -> 0.61333333 | J37: =D$14*J29 -> 1 | K37: =B$15*K29 -> 0.09 | L37: =C$15*L29 -> 0.44333333 | M37: =D$15*M29 -> 0.63
A38: А3 | B38: =B$12*B30 -> 0.08 | C38: =C$12*C30 -> 0.31666667 | D38: =D$12*D30 -> 0.63 | E38: =B$13*E30 -> 0.08 | F38: =C$13*F30 -> 0.20869565 | G38: =D$13*G30 -> 0.5 | H38: =B$14*H30 -> 0.2 | I38: =C$14*I30 -> 0.43444444 | J38: =D$14*J30 -> 0.8 | K38: =B$15*K30 -> 0.15 | L38: =C$15*L30 -> 0.44333333 | M38: =D$15*M30 -> 0.63
A39: А4 | B39: =B$12*B31 -> 0.2 | C39: =C$12*C31 -> 0.42222222 | D39: =D$12*D31 -> 0.81 | E39: =B$13*E31 -> 0.088888889 | F39: =C$13*F31 -> 0.25263158 | G39: =D$13*G31 -> 0.5 | H39: =B$14*H31 -> 0.3 | I39: =C$14*I31 -> 0.58777778 | J39: =D$14*J31 -> 0.9 | K39: =B$15*K31 -> 0.18 | L39: =C$15*L31 -> 0.48555556 | M39: =D$15*M31 -> 0.7
A40: FPIS(A+) | B40: 1 | C40: 1 | D40: 1 | E40: 1 | F40: 1 | G40: 1 | H40: 1 | I40: 1 | J40: 1 | K40: 1 | L40: 1 | M40: 1
A41: FNIS(A-) | B41: 0 | C41: 0 | D41: 0 | E41: 0 | F41: 0 | G41: 0 | H41: 0 | I41: 0 | J41: 0 | K41: 0 | L41: 0 | M41: 0
A43: 5. Расстояние до идеальных решений и коэффициент близости
A44: Альтернатив | B44: d+(K1) | C44: d+(K2) | D44: d+(K3) | E44: d+(K4) | F44: D+ | G44: d-(K1) | H44: d-(K2) | I44: d-(K3) | J44: d-(K4) | K44: D- | L44: CC | M44: Ранг
A45: А1 | B45: =SQRT((B36-B$40)^2+ (C36-C$40)^2+(D36-D$40)^2) -> 0.92317554 | C45: =SQRT((E36-E$40)^2+ (F36-F$40)^2+(G36-G$40)^2) -> 1.2324101 | D45: =SQRT((H36-H$40)^2+ (I36-I$40)^2+(J36-J$40)^2) -> 0.89995953 | E45: =SQRT((K36-K$40)^2+ (L36-L$40)^2+(M36-M$40)^2) -> 1.2470543 | F45: =SUM(B45:E45) -> 4.3025994 | G45: =SQRT((B36-B$41)^2+ (C36-C$41)^2+(D36-D$41)^2) -> 1.0504114 | H45: =SQRT((E36-E$41)^2+ (F36-F$41)^2+(G36-G$41)^2) -> 0.71410481 | I45: =SQRT((H36-H$41)^2+ (I36-I$41)^2+(J36-J$41)^2) -> 1.1770653 | J45: =SQRT((K36-K$41)^2+ (L36-L$41)^2+(M36-M$41)^2) -> 0.59032006 | K45: =SUM(G45:J45) -> 3.5319016 | L45: =K45/(F45+K45) -> 0.45081385 | M45: =RANK(L45,L45:L48) -> 2
A46: А2 | B46: =SQRT((B37-B$40)^2+ (C37-C$40)^2+(D37-D$40)^2) -> 1.1140772 | C46: =SQRT((E37-E$40)^2+ (F37-F$40)^2+(G37-G$40)^2) -> 1.159802 | D46: =SQRT((H37-H$40)^2+ (I37-I$40)^2+(J37-J$40)^2) -> 0.84380751 | E46: =SQRT((E37-E$40)^2+ (F37-F$40)^2+(G37-G$40)^2) -> 1.159802 | F46: =SUM(B46:E46) -> 4.2774887 | G46: =SQRT((B37-B$41)^2+ (C37-C$41)^2+(D37-D$41)^2) -> 0.90740847 | H46: =SQRT((E37-E$41)^2+ (F37-F$41)^2+(G37-G$41)^2) -> 1.0428923 | I46: =SQRT((H37-H$41)^2+ (I37-I$41)^2+(J37-J$41)^2) -> 1.1994489 | J46: =SQRT((K37-K$41)^2+ (L37-L$41)^2+(M37-M$41)^2) -> 0.77559296 | K46: =SUM(G46:J46) -> 3.9253427 | L46: =K46/(F46+K46) -> 0.47853509 | M46: =RANK(L46,L45:L48) -> 1
...

Sheet МАИ
A1: Чёткий коллективный МАИ
A2: Попарные сравнения по шкале Саати (1–9) → агрегация AIJ (среднее геометрическое) → расчёт приоритетов → проверка согласованности (CR ≤ 0,1) → итоговый рейтинг.
A4: 1. Альтернативы
A5: Код | B5: Концепции
A6: A1 | B6: Система управления заявками на обслуживание (FixDesk)
A7: A2 | B7: Фитнес-приложение с геймификацией
A8: A3 | B8: Сервис совместного выбора и просмотра фильмов
A9: A4 | B9: Сервис персонализированных погодных рекомендаций
A11: 2. Критерии
A12: Код | B12: Критерий
A13: K1 | B13: Масштабируемость
A14: K2 | B14: Трудоёмкость разработки MVP
A15: K3 | B15: Практическая полезность
A16: K4 | B16: Функциональная уникальность
A18: 3. Групповая матрица сравнения критериев
A19: Код | B19: K1 | C19: K2 | D19: K3 | E19: K4 | F19: Ср. геом. | G19: Приоритет
A20: K1 | B20: =1 -> 1 | C20: =POWER(C84*K84*S84,1/3) -> 0.43679023 | D20: =POWER(D84*L84*T84,1/3) -> 0.5 | E20: =POWER(E84*M84*U84,1/3) -> 0.79370053 | F20: =POWER(PRODUCT(B20:E20),1/4) -> 0.64524537 | G20: =F20/SUM($F$20:$F$23) -> 0.15249664
A21: K2 | B21: =1/C20 -> 2.2894285 | C21: =1 -> 1 | D21: =POWER(D85*L85*T85,1/3) -> 1.259921 | E21: =POWER(E85*M85*U85,1/3) -> 1.8171206 | F21: =POWER(PRODUCT(B21:E21),1/4) -> 1.5130857 | G21: =F21/SUM($F$20:$F$23) -> 0.35760116
A22: K3 | B22: =1/D20 -> 2 | C22: =1/D21 -> 0.79370053 | D22: =1 -> 1 | E22: =POWER(E86*M86*U86,1/3) -> 1.5874011 | F22: =POWER(PRODUCT(B22:E22),1/4) -> 1.259921 | G22: =F22/SUM($F$20:$F$23) -> 0.29776847
A23: K4 | B23: =1/E20 -> 1.259921 | C23: =1/E21 -> 0.55032121 | D23: =1/E22 -> 0.62996052 | E23: =1 -> 1 | F23: =POWER(PRODUCT(B23:E23),1/4) -> 0.81295823 | G23: =F23/SUM($F$20:$F$23) -> 0.19213373
A24: Σ | B24: =SUM(B20:B23) -> 6.5493495 | C24: =SUM(C20:C23) -> 2.780812 | D24: =SUM(D20:D23) -> 3.3898816 | E24: =SUM(E20:E23) -> 5.1982222 | F24: =SUM(F20:F23) -> 4.2312104 | G24: =SUM(G20:G23) -> 1
A25: w | B25: =G20 -> 0.15249664 | C25: =G21 -> 0.35760116 | D25: =G22 -> 0.29776847 | E25: =G23 -> 0.19213373
A26: λmax | B26: =SUMPRODUCT(B24:E24,B25:E25) -> 4.001329 | C26: CI | D26: =(B26-4)/3 -> 0.00044301507 | E26: CR | F26: =D26/0.9 -> 0.00049223897 | G26: =IF(F26<=0.1,"OK","Проверить") -> OK
A28: 4. Групповая матрица A1–A4 по K1 (масштабируемость)
A29: Код | B29: A1 | C29: A2 | D29: A3 | E29: A4 | F29: Ср. геом. | G29: Приоритет
A30: A1 | B30: =1 -> 1 | C30: =POWER(C94*K94*S94,1/3) -> 1.259921 | D30: =POWER(D94*L94*T94,1/3) -> 2.6207414 | E30: =POWER(E94*M94*U94,1/3) -> 1 | F30: =POWER(PRODUCT(B30:E30),1/4) -> 1.3480062 | G30: =F30/SUM($F$30:$F$33) -> 0.31299605
A31: A2 | B31: =1/C30 -> 0.79370053 | C31: =1 -> 1 | D31: =POWER(D95*L95*T95,1/3) -> 2.6207414 | E31: =POWER(E95*M95*U95,1/3) -> 1 | F31: =POWER(PRODUCT(B31:E31),1/4) -> 1.200937 | G31: =F31/SUM($F$30:$F$33) -> 0.27884778
A32: A3 | B32: =1/D30 -> 0.38157141 | C32: =1/D31 -> 0.38157141 | D32: =1 -> 1 | E32: =POWER(E96*M96*U96,1/3) -> 0.38157141 | F32: =POWER(PRODUCT(B32:E32),1/4) -> 0.48549177 | G32: =F32/SUM($F$30:$F$33) -> 0.11272724
A33: A4 | B33: =1/E30 -> 1 | C33: =1/E31 -> 1 | D33: =1/E32 -> 2.6207414 | E33: =1 -> 1 | F33: =POWER(PRODUCT(B33:E33),1/4) -> 1.2723484 | G33: =F33/SUM($F$30:$F$33) -> 0.29542893
A34: Σ | B34: =SUM(B30:B33) -> 3.1752719 | C34: =SUM(C30:C33) -> 3.6414925 | D34: =SUM(D30:D33) -> 8.8622242 | E34: =SUM(E30:E33) -> 3.3815714 | F34: =SUM(F30:F33) -> 4.3067833 | G34: =SUM(G30:G33) -> 1
A35: w | B35: =G30 -> 0.31299605 | C35: =G31 -> 0.27884778 | D35: =G32 -> 0.11272724 | E35: =G33 -> 0.29542893
A36: λmax | B36: =SUMPRODUCT(B34:E34,B35:E35) -> 4.0072977 | C36: CI | D36: =(B36-4)/3 -> 0.0024325791 | E36: CR | F36: =D36/0.9 -> 0.0027028657 | G36: =IF(F36<=0.1,"OK","Проверить") -> OK
A38: 5. Групповая матрица A1–A4 по K2 (трудоёмкость MVP)
A39: Код | B39: A1 | C39: A2 | D39: A3 | E39: A4 | F39: Ср. геом. | G39: Приоритет
A40: A1 | B40: =1 -> 1 | C40: =POWER(C104*K104*S104,1/3) -> 2 | D40: =POWER(D104*L104*T104,1/3) -> 4.6415888 | E40: =POWER(E104*M104*U104,1/3) -> 2 | F40: =POWER(PRODUCT(B40:E40),1/4) -> 2.0757816 | G40: =F40/SUM($F$40:$F$43) -> 0.44770906
A41: A2 | B41: =1/C40 -> 0.5 | C41: =1 -> 1 | D41: =POWER(D105*L105*T105,1/3) -> 2.6207414 | E41: =POWER(E105*M105*U105,1/3) -> 1 | F41: =POWER(PRODUCT(B41:E41),1/4) -> 1.0699132 | G41: =F41/SUM($F$40:$F$43) -> 0.23076119
A42: A3 | B42: =1/D40 -> 0.21544347 | C42: =1/D41 -> 0.38157141 | D42: =1 -> 1 | E42: =POWER(E106*M106*U106,1/3) -> 0.38157141 | F42: =POWER(PRODUCT(B42:E42),1/4) -> 0.42084411 | G42: =F42/SUM($F$40:$F$43) -> 0.090768565
A43: A4 | B43: =1/E40 -> 0.5 | C43: =1/E41 -> 1 | D43: =1/E42 -> 2.6207414 | E43: =1 -> 1 | F43: =POWER(PRODUCT(B43:E43),1/4) -> 1.0699132 | G43: =F43/SUM($F$40:$F$43) -> 0.23076119
A44: Σ | B44: =SUM(B40:B43) -> 2.2154435 | C44: =SUM(C40:C43) -> 4.3815714 | D44: =SUM(D40:D43) -> 10.883072 | E44: =SUM(E40:E43) -> 4.3815714 | F44: =SUM(F40:F43) -> 4.6364521 | G44: =SUM(G40:G43) -> 1
A45: w | B45: =G40 -> 0.44770906 | C45: =G41 -> 0.23076119 | D45: =G42 -> 0.090768565 | E45: =G43 -> 0.23076119
...

Sheet Итоги
A1: Фаза 1: Итоги выбора концепции
A3: 1. Сравнение результатов двух методов
A4: Код | B4: Концепции | F4: CC TOPSIS | G4: Место TOPSIS | H4: Приоритет МАИ | I4: Место МАИ
A5: A1 | B5: ='Концепции и оценки'!B5 -> Система управления заявками на обслуживание | F5: =Topsis!L45 -> 0.45081385 | G5: =Topsis!M45 -> 2 | H5: ='МАИ'!F71 -> 0.30354964 | I5: ='МАИ'!G71 -> 2
A6: A2 | B6: ='Концепции и оценки'!B6 -> Фитнес-приложение с геймификацией | F6: =Topsis!L46 -> 0.47853509 | G6: =Topsis!M46 -> 1 | H6: ='МАИ'!F72 -> 0.31867297 | I6: ='МАИ'!G72 -> 1
A7: A3 | B7: ='Концепции и оценки'!B7 -> Сервис совместного выбора и просмотра фильмов | F7: =Topsis!L47 -> 0.38114543 | G7: =Topsis!M47 -> 4 | H7: ='МАИ'!F73 -> 0.12546341 | I7: ='МАИ'!G73 -> 4
A8: A4 | B8: ='Концепции и оценки'!B8 -> Сервис персонализированных погодных рекомендаций | F8: =Topsis!L48 -> 0.44318081 | G8: =Topsis!M48 -> 3 | H8: ='МАИ'!F74 -> 0.25231398 | I8: ='МАИ'!G74 -> 3
A11: Победитель TOPSIS | D11: {=INDEX($B$5:$B$8,MATCH(1,$G$5:$G$8,0))} -> Фитнес-приложение с геймификацией
A12: Победитель МАИ | D12: {=INDEX($B$5:$B$8,MATCH(1,$I$5:$I$8,0))} -> Фитнес-приложение с геймификацией
